Workbook

Sheet Dashboard
A1: Book Library Management — Project Tracker
A2: AI-SDLC build process · product → modules → features → packets · updated live
A4: Progress at a glance
A5: Stage | B5: Total | C5: Done | D5: In progress | E5: Blocked | F5: % Done
A6: Product docs (24) | B6: =COUNTA('Product Docs'!B5:B28) | C6: =COUNTIF('Product Docs'!D5:D28,"Done") | D6: =COUNTIF('Product Docs'!D5:D28,"In progress") | E6: =COUNTIF('Product Docs'!D5:D28,"Blocked") | F6: =IFERROR(C6/B6,0)
A7: Packets — BRD | B7: =COUNTA(Packets!B5:B17) | C7: =COUNTIF(Packets!E5:E17,"Done") | D7: =COUNTIF(Packets!E5:E17,"In progress") | E7: =COUNTIF(Packets!E5:E17,"Blocked") | F7: =IFERROR(C7/B7,0)
A8: Packets — DESIGN | B8: =COUNTA(Packets!B5:B17) | C8: =COUNTIF(Packets!F5:F17,"Done") | D8: =COUNTIF(Packets!F5:F17,"In progress") | E8: =COUNTIF(Packets!F5:F17,"Blocked") | F8: =IFERROR(C8/B8,0)
A9: Packets — BUILD prompt | B9: =COUNTA(Packets!B5:B17) | C9: =COUNTIF(Packets!G5:G17,"Done") | D9: =COUNTIF(Packets!G5:G17,"In progress") | E9: =COUNTIF(Packets!G5:G17,"Blocked") | F9: =IFERROR(C9/B9,0)
A10: Packets — Execution | B10: =COUNTA(Packets!B5:B17) | C10: =COUNTIF(Packets!H5:H17,"Done") | D10: =COUNTIF(Packets!H5:H17,"In progress") | E10: =COUNTIF(Packets!H5:H17,"Blocked") | F10: =IFERROR(C10/B10,0)
A11: Packets — ENG-QA prompt | B11: =COUNTA(Packets!B5:B17) | C11: =COUNTIF(Packets!I5:I17,"Done") | D11: =COUNTIF(Packets!I5:I17,"In progress") | E11: =COUNTIF(Packets!I5:I17,"Blocked") | F11: =IFERROR(C11/B11,0)
A12: Packets — Evidence (gate) | B12: =COUNTA(Packets!B5:B17) | C12: =COUNTIF(Packets!J5:J17,"Done") | D12: =COUNTIF(Packets!J5:J17,"In progress") | E12: =COUNTIF(Packets!J5:J17,"Blocked") | F12: =IFERROR(C12/B12,0)
A15: Legend
A16: Done | B16: Authored / executed / gate green — depending on the stage.
A17: In progress | B17: Started but not yet meeting the stage's done definition.
A18: Blocked | B18: Cannot proceed — see linked Open Question or note in the row.
A19: Not started | B19: Nothing written or executed yet.
A22: How to use
A23: 1. Update Status cells on the Product Docs and Packets sheets — KPI cards roll up automatically.
A24: 2. Acceptance Criteria sheet tracks per-AC verdicts captured by QA sessions; mark each as Pass / Fail once the packet's Evidence.md closes.
A25: 3. Open Questions: anything Blocker bounces the Status of dependent rows in other sheets.
A26: 4. Keep the Owner column current — it tells the next session who's accountable.
A27: 5. The Notes column on Packets is the spot for a one-line build/QA summary that the next session reads before resuming.
A29: Resume on a new day
A30: Read CLAUDE.md at the project root first. It lists current state, packet status, design tokens, run commands, and the next packet to execute. Last updated: 2026-06-29.

Sheet Product Docs
A1: Stage 1 · Product Planning Documents
A2: 24 docs across Discovery → Phase A–F. Status currently reflects what the agent has authored.
A4: Phase | B4: ID | C4: File | D4: Status | E4: Owner | F4: Last updated | G4: Notes
A5: Discovery | B5: D0 | C5: D0-BRD.md | D5: Done | E5: Builder | F5: 2026-06-23 | G5: Stack constraints updated to Postgres-only; frontend-skill note added.
A6: Discovery | B6: OQ | C6: OQ-OPEN-QUESTIONS.md | D6: Done | E6: Builder | F6: 2026-06-23 | G6: OQ-002 resolved; OQ-001 still open.
A7: Phase A | B7: D1 | C7: D1-ROADMAP.md | D7: Done | E7: Builder | F7: 2026-06-23 | G7: Two drops: walking skeleton + polish/deploy.
A8: Phase A | B8: D2 | C8: D2-PRD.md | D8: Done | E8: Builder | F8: 2026-06-23 | G8: 5 user journeys.
A9: Phase A | B9: D15a | C9: D15a-USER-STORIES-v1.md | D9: Done | E9: Builder | F9: 2026-06-23 | G9: 12 stories US-01..US-12.
A10: Phase A | B10: D5 | C10: D5-ARCHITECTURE.md | D10: Done | E10: Builder | F10: 2026-06-23 | G10: Postgres + Alembic; folder layout updated.
A11: Phase A | B11: D5b | C11: D5b-AI-READINESS.md | D11: Done | E11: Builder | F11: 2026-06-23 | G11: Composite 41/45 → AI-led.
A12: Phase B | B12: D3 | C12: D3-FEATURE-CATALOG.md | D12: Done | E12: Builder | F12: 2026-06-23 | G12: 9 features mapped to packets.
A13: Phase B | B13: D10 | C13: D10-QUALITY-NFRs.md | D13: Done | E13: Builder | F13: 2026-06-23 | G13: 10 NFRs, binary thresholds.
A14: Phase B | B14: D12 | C14: D12-SECURITY.md | D14: Done | E14: Builder | F14: 2026-06-23 | G14: 10 threats, mitigations + backup note updated.
A15: Phase C | B15: D6 | C15: D6-DATA-MODEL.md | D15: Done | E15: Builder | F15: 2026-06-23 | G15: Postgres-native DDL (BIGSERIAL, TIMESTAMPTZ, functional indexes).
... A30: Phase F | B30: F2 | C30: F2-HANDOFF.md | D30: Done | E30: Builder | F30: 2026-06-23 | G30: QA-session boot prompt.

Sheet Packets
A1: Stage 2-3 · Packets (5-file cycle)
A2: BRD · DESIGN · BUILD prompt authored up front. Execution → ENG-QA prompt → Evidence close the gate.
A4: Packet | B4: Module | C4: Title | D4: Depends on | E4: BRD | F4: DESIGN | G4: BUILD prompt | H4: Execution | I4: ENG-QA prompt | J4: Evidence | K4: Branch | L4: Owner | M4: Notes
A5: S-001 | B5: database | C5: Postgres + ORM + Alembic baseline | D5: — | E5: Done | F5: Done | G5: Done | H5: Done | I5: Done | J5: Done | K5: packet/S-001-postgres-orm-alembic | L5: Builder | M5: GREEN. All 7 ACs proven. Native Postgres 17 substitution recorded in Evidence.
A6: S-002 | B6: backend | C6: FastAPI skeleton + DB session + CORS | D6: S-001 | E6: Done | F6: Done | G6: Done | H6: Done | I6: Done | J6: Done | K6: packet/S-002-fastapi-skeleton | L6: Builder | M6: GREEN. /healthz live + DB ping; CORS allow/deny verified.
A7: S-003 | B7: backend | C7: POST /books | D7: S-002 | E7: Done | F7: Done | G7: Done | H7: Done | I7: Done | J7: Done | K7: packet/S-003-post-books | L7: Builder | M7: GREEN. Status canonicalization works ('read' -> 'Read').
A8: S-004 | B8: backend | C8: GET /books, GET /books/{id} | D8: S-003 | E8: Done | F8: Done | G8: Done | H8: Done | I8: Done | J8: Done | K8: packet/S-004-get-books | L8: Builder | M8: GREEN. HARD_LIMIT=1000 (T-05); 6 tests + EXPLAIN ANALYZE on functional index.
A9: S-005 | B9: backend | C9: PUT /books/{id} | D9: S-004 | E9: Done | F9: Done | G9: Done | H9: Done | I9: Done | J9: Done | K9: packet/S-005-put-books | L9: Builder | M9: GREEN. PUT preserves created_at by design (BookUpdate omits the field).
A10: S-006 | B10: backend | C10: DELETE /books/{id} | D10: S-005 | E10: Done | F10: Done | G10: Done | H10: Done | I10: Done | J10: Done | K10: packet/S-006-delete-books | L10: Builder | M10: GREEN. 204 + empty body; psql confirms row gone.
A11: S-007 | B11: backend | C11: Search + filter query params | D11: S-006 | E11: Done | F11: Done | G11: Done | H11: Done | I11: Done | J11: Done | K11: packet/S-007-search-filter | L11: Builder | M11: GREEN. Median latency 17.9 ms with 1000 rows (NFR Q-005 < 50 ms).
A12: S-008 | B12: frontend | C12: Home page + frontend scaffolding | D12: S-007 | E12: Done | F12: Done | G12: Done | H12: Done | I12: Done | J12: Done | K12: packet/S-008-home-page | L12: Builder | M12: GREEN. frontend-design + ui-ux-pro-max committed tokens.js; spine-shelf hero.
A13: S-009 | B13: frontend | C13: Books page (list + delete) | D13: S-006,S-008 | E13: Done | F13: Done | G13: Done | H13: Done | I13: Done | J13: Done | K13: packet/S-009-books-page | L13: Builder | M13: GREEN. BookCard mirrors home shelf color; ConfirmModal focus-trapped.
A14: S-010 | B14: frontend | C14: AddBook page + shared BookForm | D14: S-003,S-009 | E14: Done | F14: Done | G14: Done | H14: Done | I14: Done | J14: Done | K14: packet/S-010-add-book-page | L14: Builder | M14: GREEN. Shared BookForm contract finalized. Two bugs found+fixed mid-cycle.
A15: S-011 | B15: frontend | C15: EditBook page | D15: S-005,S-010 | E15: Done | F15: Done | G15: Done | H15: Done | I15: Done | J15: Done | K15: packet/S-011-edit-book-page | L15: Builder | M15: GREEN. FormSkeleton matches BookForm rhythm; BookForm untouched (SHA verified). 5 EditBook tests pass; 23 total. Build 79.28 KB gzip.
... A17: S-013 | B17: infra | C17: README + deploy + final gate | D17: all | E17: Done | F17: Done | G17: Done | H17: Done | I17: Done | J17: Done | K17: packet/S-013-readme-deploy | L17: Builder | M17: GREEN with deferrals. README + CI workflow + git init + initial commit (3dcb799). AC3 (live CI) and AC5 (clean-clone smoke on second machine) explicitly deferred per user direction; OQ-001 stays Open (deferred). All 6 ACs structurally met; see Evidence.md §Deferrals.

Sheet Acceptance Criteria
A1: Acceptance Criteria · per-packet binary checks
A2: Each AC is binary (Pass / Fail). Verdicts populated by the QA session that authors Evidence.md.
A4: Packet | B4: AC | C4: Description | D4: Source (TC / US) | E4: Verdict | F4: Notes
A5: S-001 | B5: AC1 | C5: docker compose up db boots Postgres on :5432 with named volume. | D5: D6 | E5: Pass
A6: S-001 | B6: AC2 | C6: db_test service or db_test database available for tests. | D6: D11 §2 | E6: Pass
A7: S-001 | B7: AC3 | C7: backend/models.py Book matches D6 exactly (columns, types, CHECK, indexes). | D7: D6 §3 | E7: Pass
A8: S-001 | B8: AC4 | C8: database.py exposes engine, SessionLocal, get_db. | D8: D5 §5 | E8: Pass
A9: S-001 | B9: AC5 | C9: alembic upgrade head materializes the books table per D6 §2. | D9: D6 | E9: Pass
A10: S-001 | B10: AC6 | C10: alembic downgrade base then upgrade head is idempotent. | D10: D14 | E10: Pass
A11: S-001 | B11: AC7 | C11: All four indexes from D6 present after upgrade head. | D11: D6 §2 | E11: Pass
A12: S-002 | B12: AC1 | C12: uvicorn boots against live Postgres. | D12: D5 | E12: Pass
A13: S-002 | B13: AC2 | C13: GET /docs → 200. | D13: D7 | E13: Pass
A14: S-002 | B14: AC3 | C14: GET /openapi.json → 200 + valid JSON. | D14: D7 | E14: Pass
A15: S-002 | B15: AC4 | C15: GET /healthz returns {status:ok, db:ok}; db field reflects SELECT 1. | D15: D5 | E15: Pass
A16: S-002 | B16: AC5 | C16: CORS allows :5173, denies foreign origin. | D16: D12 §T-07 | E16: Pass
... A56: S-008 | B56: AC9 | C56: Lint + smoke tests pass. | D56: D11 | E56: Pass
A57: S-008 | B57: AC10 | C57: frontend-design + ui-ux-pro-max invoked; tokens.js committed. | D57: D18 §0 | E57: Pass | F57: Mandatory.
A58: S-009 | B58: AC1 | C58: Books page lists cards in 1/2/3 col grid. | D58: D9 §3 | E58: Pass
A59: S-009 | B59: AC2 | C59: Empty state with Add CTA. | D59: OQ-007 | E59: Pass
A60: S-009 | B60: AC3 | C60: Card shows title/author/genre/status + Edit/Delete. | D60: D9 §6 | E60: Pass
A61: S-009 | B61: AC4 | C61: Delete confirm modal then removes card without reload. | D61: TC-062 | E61: Pass
A62: S-009 | B62: AC5 | C62: Failed delete shows red toast; card stays. | D62: Q-006 | E62: Pass
A63: S-009 | B63: AC6 | C63: Edit link navigates to /edit/:id. | D63: D9 §5 | E63: Pass
A64: S-009 | B64: AC7 | C64: <script> in book_name renders as text. | D64: TC-081 / T-02 | E64: Pass
A65: S-009 | B65: AC8 | C65: 360 px layout intact. | D65: Q-003 | E65: Pass
A66: S-009 | B66: AC9 | C66: Lint + tests pass. | D66: D11 | E66: Pass
A67: S-009 | B67: AC10 | C67: FE skills minuted; tokens extended. | D67: D18 §0 | E67: Pass | F67: Mandatory.
A68: S-010 | B68: AC1 | C68: Add page renders BookForm with 4 fields. | D68: D9 §4 | E68: Pass
A69: S-010 | B69: AC2 | C69: Inline errors per field on empty submit. | D69: US-12 AC1 | E69: Pass
A70: S-010 | B70: AC3 | C70: Status as radio (Read/Unread). | D70: D9 §6 | E70: Pass
A71: S-010 | B71: AC4 | C71: Successful POST → toast + redirect to /books. | D71: D9 §4 | E71: Pass
A72: S-010 | B72: AC5 | C72: API 422 maps to field-level errors. | D72: US-12 AC2 | E72: Pass
A73: S-010 | B73: AC6 | C73: Form keyboard-navigable; Enter submits. | D73: Q-002 | E73: Pass
A74: S-010 | B74: AC7 | C74: Submit disabled in-flight; no double-submit. | D74: Q-006 | E74: Pass
A75: S-010 | B75: AC8 | C75: Lint + tests + 360 px clean. | D75: D11 | E75: Pass
A76: S-010 | B76: AC9 | C76: FE skills invoked for form treatment. | D76: D18 §0 | E76: Pass | F76: Mandatory.
A77: S-011 | B77: AC1 | C77: Edit page prefills from GET /books/{id}. | D77: US-03 AC5 | E77: Pass
A78: S-011 | B78: AC2 | C78: Skeleton placeholder while loading; no layout jump. | D78: D9 §5 | E78: Pass
A79: S-011 | B79: AC3 | C79: PUT success → toast + redirect to /books. | D79: D7 | E79: Pass
A80: S-011 | B80: AC4 | C80: 404 on load → redirect /books + error toast. | D80: D16 | E80: Pass
...

Sheet Open Questions
A1: Open Questions
A2: Blockers halt downstream packets. Resolve, then mirror the decision into the relevant doc.
A4: ID | B4: Question | C4: Status | D4: Affects | E4: Decision / Resolution | F4: Owner | G4: Updated
A5: OQ-001 | B5: Production deploy target (Render+Vercel vs Railway vs Fly). | C5: Open (deferred) | D5: D13, S-013 | E5: Deferred past S-013 close at user direction (2026-06-29). README §Deploy documents Render + Vercel illustratively. | F5: Builder | G5: 2026-06-29
A6: OQ-002 | B6: Database choice across environments. | C6: Resolved | D6: D5, D6, D11, D13, D14, D16 | E6: PostgreSQL in dev/test/prod; docker-compose locally; managed in prod. No SQLite. | F6: Builder | G6: 2026-06-23
A7: OQ-003 | B7: genre free-text vs enum? | C7: Resolved | D7: D6, S-007, S-012 | E7: Free-text in v1; UI dropdown populated from distinct values in current results. | F7: Builder | G7: 2026-06-23
A8: OQ-004 | B8: created_at format from API. | C8: Resolved | D8: D7 | E8: UTC ISO 8601 from API; humanize client-side via Intl.RelativeTimeFormat. | F8: Builder | G8: 2026-06-23
A9: OQ-005 | B9: Client- or server-side stats? | C9: Resolved | D9: F-007, S-008 | E9: Client-side from GET /books in v1; server endpoint when row count grows past 1k. | F9: Builder | G9: 2026-06-23
A10: OQ-006 | B10: Normalize status case on input? | C10: Resolved | D10: S-003, S-005 | E10: Accept case-insensitive; persist canonical 'Read'/'Unread'. | F10: Builder | G10: 2026-06-23
A11: OQ-007 | B11: Books page empty state. | C11: Resolved | D11: S-009 | E11: Centered empty-state card with 'Add your first book' CTA. | F11: Builder | G11: 2026-06-23

Sheet User Stories
A1: User Stories
A2: Business-language US-01..US-12 with build-precise links to features and packets.
A4: ID | B4: Story | C4: Features | D4: Packets | E4: Status | F4: Notes
A5: US-01 | B5: Add a book to my library. | C5: F-002, F-004 | D5: S-003, S-010 | E5: Done | F5: S-003 + S-010 both green.
A6: US-02 | B6: See all my books on one page. | C6: F-003 | D6: S-004, S-009 | E6: Done | F6: S-004 + S-009 both green.
A7: US-03 | B7: Edit a book's details. | C7: F-002, F-004 | D7: S-005, S-011 | E7: Done | F7: S-005 + S-011 both green.
A8: US-04 | B8: Delete a book. | C8: F-002, F-003 | D8: S-006, S-009 | E8: Done | F8: S-006 + S-009 both green.
A9: US-05 | B9: Search by title or author. | C9: F-005 | D9: S-007, S-012 | E9: Done | F9: S-007 + S-012 both green.
A10: US-06 | B10: Filter by author. | C10: F-006 | D10: S-007, S-012 | E10: Done | F10: S-007 + S-012 both green.
A11: US-07 | B11: Filter by genre. | C11: F-006 | D11: S-007, S-012 | E11: Done | F11: S-007 + S-012 both green.
A12: US-08 | B12: Filter by reading status. | C12: F-006 | D12: S-007, S-012 | E12: Done | F12: S-007 + S-012 both green.
A13: US-09 | B13: See how many books / how many read. | C13: F-007 | D13: S-008 | E13: Done | F13: S-008 covers stats client-side.
A14: US-10 | B14: A friendly home page. | C14: F-001 | D14: S-008 | E14: Done | F14: S-008 hero + features + stats + CTAs.
A15: US-11 | B15: Use the app on my phone. | C15: F-001..F-006 | D15: S-008..S-012 (Q-003) | E15: Done | F15: S-008..S-012 honor Q-003 (responsive at 360 px) in tests.
A16: US-12 | B16: Inline form errors next to fields. | C16: F-004 | D16: S-010, S-011 | E16: Done | F16: S-010 inline errors with aria-describedby.
